Workbook

Sheet Working
J1: Niy | K1: 25000 | L1: Dhar | M1: 26000 | N1: Pwan ( line) | O1: 15000 | P1: Pawan | Q1: 300
A2: 179YK295MULTI - 1197
A3: Row Labels | B3: Expenses | C3: Total Expenses | D3: Percentage | E3: Niy | F3: Dhar | G3: Pwan ( Line) | H3: Pawan | J3: Pawan | K3: Niy | L3: Dhar | M3: Pawan | S3: n | T3: p
A4: 45749 | B4: 2308.75 | C4: 16297 | D4: =+B4/C4*100 -> 14.166718 | E4: =+ROUND(K4/100*D4,0) -> 127 | F4: =+L4/100*D4 -> 89.250322 | G4: =+M4/100*D4 -> 81.741962 | H4: =+J4/100*D4 -> 0 | J4: 0 | K4: 893 | L4: 630 | M4: 577 | S4: 9 | T4: 15
A5: 45750 | B5: 10375 | C5: 17812.25 | D5: =+B5/C5*100 -> 58.246432 | E5: =+ROUND(K5/100*D5,0) -> 520 | F5: =+L5/100*D5 -> 366.95252 | G5: =+M5/100*D5 -> 336.08191 | H5: =+J5/100*D5 -> 0 | J5: 0 | K5: 893 | L5: 630 | M5: 577 | S5: 13
A6: 45751 | B6: 13290 | C6: 21612 | D6: =+B6/C6*100 -> 61.493615 | E6: =+ROUND(K6/100*D6,0) -> 549 | F6: =+L6/100*D6 -> 387.40977 | G6: =+M6/100*D6 -> 354.81816 | H6: =+J6/100*D6 -> 184.48084 | J6: 300 | K6: 893 | L6: 630 | M6: 577
A7: 45752 | B7: 9753.75 | C7: 21954 | D7: =+B7/C7*100 -> 44.428122 | E7: =+ROUND(K7/100*D7,0) -> 397 | F7: =+L7/100*D7 -> 279.89717 | G7: =+M7/100*D7 -> 256.35027 | H7: =+J7/100*D7 -> 133.28437 | J7: 300 | K7: 893 | L7: 630 | M7: 577
A8: 45753 | B8: 5408.3333 | C8: 15988.571 | D8: =+B8/C8*100 -> 33.826245 | E8: =+ROUND(K8/100*D8,0) -> 302 | F8: =+L8/100*D8 -> 213.10534 | G8: =+M8/100*D8 -> 0 | H8: =+J8/100*D8 -> 101.47873 | J8: 300 | K8: 893 | L8: 630 | M8: 0
A9: 45754 | B9: 2963.75 | C9: 20359.389 | D9: =+B9/C9*100 -> 14.557166 | E9: =+ROUND(K9/100*D9,0) -> 130 | F9: =+L9/100*D9 -> 91.710145 | G9: =+M9/100*D9 -> 83.994847 | H9: =+J9/100*D9 -> 43.671497 | J9: 300 | K9: 893 | L9: 630 | M9: 577
A10: 45755 | B10: 1243.75 | C10: 21300.2 | D10: =+B10/C10*100 -> 5.8391471 | E10: =+ROUND(K10/100*D10,0) -> 52 | F10: =+L10/100*D10 -> 36.786626 | G10: =+M10/100*D10 -> 33.691878 | H10: =+J10/100*D10 -> 17.517441 | J10: 300 | K10: 893 | L10: 630 | M10: 577
A11: 45756 | B11: 605 | C11: 20744 | D11: =+B11/C11*100 -> 2.916506 | E11: =+ROUND(K11/100*D11,0) -> 0 | F11: =+L11/100*D11 -> 18.373988 | G11: =+M11/100*D11 -> 16.828239 | H11: =+J11/100*D11 -> 0 | J11: 0 | K11: 0 | L11: 630 | M11: 577
A12: 45761 | B12: 250 | C12: 16912 | D12: =+B12/C12*100 -> 1.4782403 | E12: =+ROUND(K12/100*D12,0) -> 13 | F12: =+L12/100*D12 -> 9.3129139 | G12: =+M12/100*D12 -> 8.5294465 | H12: =+J12/100*D12 -> 0 | J12: 0 | K12: 893 | L12: 630 | M12: 577
A13: Total | E13: =SUM(_FV(E4,"E12")) -> #VALUE! | F13: =SUM(_FV(F4,"F12")) -> #VALUE! | G13: =SUM(_FV(G4,"G12")) -> #VALUE! | H13: =SUM(_FV(H4,"H12")) -> #VALUE!
A17: 190YK214MEHROON- 1060
A18: Row Labels | B18: Expenses | C18: Total Expenses | D18: Percentage | E18: Niy | F18: Dhar | G18: Pwan ( Line) | H18: Pawan | J18: Pawan | K18: Niy | L18: Dhar | M18: Pawan
A19: 45755 | B19: 1885 | C19: 21300.2 | D19: =+B19/C19*100 -> 8.8496822 | E19: =+K19/100*D19 -> 79.027662 | F19: =+L19/100*D19 -> 55.752998 | G19: =+M19/100*D19 -> 51.062666 | H19: =+J19/100*D19 -> 26.549046 | J19: 300 | K19: 893 | L19: 630 | M19: 577
A20: 45756 | B20: 7696.25 | C20: 20744 | D20: =+B20/C20*100 -> 37.101089 | E20: =+K20/100*D20 -> 0 | F20: =+L20/100*D20 -> 233.73686 | G20: =+M20/100*D20 -> 214.07329 | H20: =+J20/100*D20 -> 0 | J20: 0 | K20: 0 | L20: 630 | M20: 577
A21: 45757 | B21: 11050 | C21: 22158 | D21: =+B21/C21*100 -> 49.869122 | E21: =+K21/100*D21 -> 445.33126 | F21: =+L21/100*D21 -> 314.17547 | G21: =+M21/100*D21 -> 287.74483 | H21: =+J21/100*D21 -> 149.60737 | J21: 300 | K21: 893 | L21: 630 | M21: 577
A22: 45758 | B22: 12292.5 | C22: 20984.4 | D22: =+B22/C22*100 -> 58.57923 | E22: =+K22/100*D22 -> 523.11253 | F22: =+L22/100*D22 -> 369.04915 | G22: =+M22/100*D22 -> 338.00216 | H22: =+J22/100*D22 -> 175.73769 | J22: 300 | K22: 893 | L22: 630 | M22: 577
A23: 45759 | B23: 6926.25 | C23: 15960 | D23: =+B23/C23*100 -> 43.397556 | E23: =+K23/100*D23 -> 387.54018 | F23: =+L23/100*D23 -> 273.40461 | G23: =+M23/100*D23 -> 250.4039 | H23: =+J23/100*D23 -> 130.19267 | J23: 300 | K23: 893 | L23: 630 | M23: 577
A24: 45761 | B24: 3168.75 | C24: 16912 | D24: =+B24/C24*100 -> 18.736696 | E24: =+K24/100*D24 -> 167.31869 | F24: =+L24/100*D24 -> 118.04118 | G24: =+M24/100*D24 -> 108.11073 | H24: =+J24/100*D24 -> 0 | J24: 0 | K24: 893 | L24: 630 | M24: 577
A25: Total | E25: =SUM(_FV(E16,"E24")) -> #VALUE! | F25: =SUM(_FV(F16,"F24")) -> #VALUE! | G25: =SUM(_FV(G16,"G24")) -> #VALUE! | H25: =SUM(_FV(H16,"H24")) -> #VALUE!
A28: 393YKGREEN -360
A29: Row Labels | B29: Expenses | C29: Total Expenses | D29: Percentage | E29: Niy | F29: Dhar | G29: Pwan ( Line) | H29: Pawan | J29: Pawan | K29: Niy | L29: Dhar | M29: Pawan
A30: 45743 | B30: 887.5 | C30: 15908.25 | D30: =+B30/C30*100 -> 5.5788663 | E30: =+K30/100*D30 -> 49.763487 | F30: =+L30/100*D30 -> 35.146858 | G30: =+M30/100*D30 -> 32.190059 | H30: =+J30/100*D30 -> 0 | J30: 0 | K30: 892 | L30: 630 | M30: 577
A31: 45744 | B31: 97.5 | C31: 7584.75 | D31: =+B31/C31*100 -> 1.2854741 | E31: =+K31/100*D31 -> 11.466429 | F31: =+L31/100*D31 -> 8.0984871 | G31: =+M31/100*D31 -> 7.4171858 | H31: =+J31/100*D31 -> 0 | J31: 0 | K31: 892 | L31: 630 | M31: 577
A32: 45745 | B32: 233.75 | C32: 12632.25 | D32: =+B32/C32*100 -> 1.8504225 | E32: =+K32/100*D32 -> 16.505769 | F32: =+L32/100*D32 -> 11.657662 | G32: =+M32/100*D32 -> 10.676938 | H32: =+J32/100*D32 -> 0 | J32: 0 | K32: 892 | L32: 630 | M32: 577
A33: 45748 | B33: 1456.25 | C33: 16626.75 | D33: =+B33/C33*100 -> 8.7584766 | E33: =+K33/100*D33 -> 78.125611 | F33: =+L33/100*D33 -> 55.178402 | G33: =+M33/100*D33 -> 50.53641 | H33: =+J33/100*D33 -> 0 | J33: 0 | K33: 892 | L33: 630 | M33: 577
A34: 45749 | B34: 2770 | C34: 16297 | D34: =+B34/C34*100 -> 16.996993 | E34: =+K34/100*D34 -> 151.61318 | F34: =+L34/100*D34 -> 107.08106 | G34: =+M34/100*D34 -> 98.072651 | H34: =+J34/100*D34 -> 0 | J34: 0 | K34: 892 | L34: 630 | M34: 577
A35: 45751 | B35: 375 | C35: 21612 | D35: =+B35/C35*100 -> 1.7351471 | E35: =+K35/100*D35 -> 15.477512 | F35: =+L35/100*D35 -> 10.931427 | G35: =+M35/100*D35 -> 10.011799 | H35: =+J35/100*D35 -> 5.2054414 | J35: 300 | K35: 892 | L35: 630 | M35: 577
A36: 45752 | B36: 250 | C36: 21954 | D36: =+B36/C36*100 -> 1.1387446 | E36: =+K36/100*D36 -> 10.157602 | F36: =+L36/100*D36 -> 7.1740913 | G36: =+M36/100*D36 -> 6.5705566 | H36: =+J36/100*D36 -> 3.4162339 | J36: 300 | K36: 892 | L36: 630 | M36: 577
A37: 45754 | B37: 3176.25 | C37: 20359.389 | D37: =+B37/C37*100 -> 15.60091 | E37: =+K37/100*D37 -> 139.16012 | F37: =+L37/100*D37 -> 98.285735 | G37: =+M37/100*D37 -> 90.017252 | H37: =+J37/100*D37 -> 46.802731 | J37: 300 | K37: 892 | L37: 630 | M37: 577
A38: 45755 | B38: 5355 | C38: 21300.2 | D38: =+B38/C38*100 -> 25.140609 | E38: =+K38/100*D38 -> 224.25423 | F38: =+L38/100*D38 -> 158.38584 | G38: =+M38/100*D38 -> 145.06131 | H38: =+J38/100*D38 -> 75.421827 | J38: 300 | K38: 892 | L38: 630 | M38: 577
A39: 45756 | B39: 2298.75 | C39: 20744 | D39: =+B39/C39*100 -> 11.081518 | E39: =+K39/100*D39 -> 0 | F39: =+L39/100*D39 -> 69.813561 | G39: =+M39/100*D39 -> 63.940356 | H39: =+J39/100*D39 -> 0 | J39: 0 | K39: 0 | L39: 630 | M39: 577
A40: 45757 | B40: 930 | C40: 22158 | D40: =+B40/C40*100 -> 4.1971297 | E40: =+K40/100*D40 -> 37.438397 | F40: =+L40/100*D40 -> 26.441917 | G40: =+M40/100*D40 -> 24.217438 | H40: =+J40/100*D40 -> 12.591389 | J40: 300 | K40: 892 | L40: 630 | M40: 577
A41: 45758 | B41: 250 | C41: 20984.4 | D41: =+B41/C41*100 -> 1.1913612 | E41: =+K41/100*D41 -> 10.626942 | F41: =+L41/100*D41 -> 7.5055756 | G41: =+M41/100*D41 -> 6.8741541 | H41: =+J41/100*D41 -> 3.5740836 | J41: 300 | K41: 892 | L41: 630 | M41: 577
... A43: 45765 | B43: 605 | C43: 20194 | D43: =+B43/C43*100 -> 2.9959394 | E43: =+K43/100*D43 -> 26.723779 | F43: =+L43/100*D43 -> 18.874418 | G43: =+M43/100*D43 -> 17.28657 | H43: =+J43/100*D43 -> 8.9878182 | J43: 300 | K43: 892 | L43: 630 | M43: 577
A44: Total | E44: =SUM(_FV(E35,"E43")) -> #VALUE! | F44: =SUM(_FV(F35,"F43")) -> #VALUE! | G44: =SUM(_FV(G35,"G43")) -> #VALUE! | H44: =SUM(_FV(H35,"H43")) -> #VALUE!
A46: 108YK148PINKRAY -570 | R46: Refersment
A47: Row Labels | B47: Expenses | C47: Total Expenses | D47: Percentage | E47: Niy | F47: Dhar | G47: Pwan ( Line) | H47: Pawan | J47: Pawan | K47: Niy | L47: Dhar | M47: Pawan | R47: Machine nun | S47: Name | T47: 108YK148PINKRAY -570
...

Sheet Undivideable Expenses
G1: 27000 | H1: =+G1/31 -> 870.96774 | O1: 16000 | Q1: =+O1/31 -> 516.12903
D2: May | G2: Dharmandar | N2: Pawan | U2: May
V3: Total Expenses | W3: Total Salary
D4: 45778 | G4: 12.19 | H4: 870.96774 | I4: =+H4/9.5 -> 91.680815 | J4: =+I4*G4 -> 1117.5891 | L4: =+J4+K4 -> 1117.5891 | N4: 12.28 | O4: 516.12 | P4: =+O4/9.5 -> 54.328421 | Q4: =+P4*N4 -> 667.15301 | S4: =+Q4+R4 -> 667.15301 | U4: 45778 | V4: =+S4+L4 -> 1784.7421 | W4: 20405.75
D5: 45779 | G5: 12.18 | H5: 870.96774 | I5: =+H5/9.5 -> 91.680815 | J5: =+I5*G5 -> 1116.6723 | L5: =+J5+K5 -> 1116.6723 | N5: 7.27 | O5: 516.12 | P5: =+O5/9.5 -> 54.328421 | Q5: =+P5*N5 -> 394.96762 | S5: =+Q5+R5 -> 394.96762 | U5: 45779 | V5: =+S5+L5 -> 1511.6399 | W5: 18853.375
D6: 45780 | G6: 9.32 | H6: 870.96774 | I6: =+H6/9.5 -> 91.680815 | J6: =+I6*G6 -> 854.4652 | L6: =+J6+K6 -> 854.4652 | N6: 9.18 | O6: 516.12 | P6: =+O6/9.5 -> 54.328421 | Q6: =+P6*N6 -> 498.73491 | S6: =+Q6+R6 -> 498.73491 | U6: 45780 | V6: =+S6+L6 -> 1353.2001 | W6: 6329.875
D7: 45781 | G7: 9.31 | H7: 870.96774 | I7: =+H7/9.5 -> 91.680815 | J7: =+I7*G7 -> 853.54839 | K7: 870.96774 | L7: =+J7+K7 -> 1724.5161 | N7: 9.3 | O7: 516.12 | P7: =+O7/9.5 -> 54.328421 | Q7: =+P7*N7 -> 505.25432 | R7: 516.12903 | S7: =+Q7+R7 -> 1021.3833 | U7: 45781 | V7: =+S7+L7 -> 2745.8995 | W7: 9181.1429
D8: 45782 | G8: 10.53 | H8: 870.96774 | I8: =+H8/9.5 -> 91.680815 | J8: =+I8*G8 -> 965.39898 | L8: =+J8+K8 -> 965.39898 | N8: 12.3 | O8: 516.12 | P8: =+O8/9.5 -> 54.328421 | Q8: =+P8*N8 -> 668.23958 | S8: =+Q8+R8 -> 668.23958 | U8: 45782 | V8: =+S8+L8 -> 1633.6386 | W8: 14211
D9: 45783 | G9: 10.14 | H9: 870.96774 | I9: =+H9/9.5 -> 91.680815 | J9: =+I9*G9 -> 929.64346 | L9: =+J9+K9 -> 929.64346 | N9: 12.05 | O9: 516.12 | P9: =+O9/9.5 -> 54.328421 | Q9: =+P9*N9 -> 654.65747 | S9: =+Q9+R9 -> 654.65747 | U9: 45783 | V9: =+S9+L9 -> 1584.3009 | W9: 14709.75
D10: 45784 | G10: 11.23 | H10: 870.96774 | I10: =+H10/9.5 -> 91.680815 | J10: =+I10*G10 -> 1029.5756 | L10: =+J10+K10 -> 1029.5756 | N10: 12.31 | O10: 516.12 | P10: =+O10/9.5 -> 54.328421 | Q10: =+P10*N10 -> 668.78286 | S10: =+Q10+R10 -> 668.78286 | U10: 45784 | V10: =+S10+L10 -> 1698.3584 | W10: 16863.625
D11: 45785 | G11: 11.57 | H11: 870.96774 | I11: =+H11/9.5 -> 91.680815 | J11: =+I11*G11 -> 1060.747 | L11: =+J11+K11 -> 1060.747 | N11: 11.49 | O11: 516.12 | P11: =+O11/9.5 -> 54.328421 | Q11: =+P11*N11 -> 624.23356 | S11: =+Q11+R11 -> 624.23356 | U11: 45785 | V11: =+S11+L11 -> 1684.9806 | W11: 16241.5
D12: 45786 | G12: 12.28 | H12: 870.96774 | I12: =+H12/9.5 -> 91.680815 | J12: =+I12*G12 -> 1125.8404 | L12: =+J12+K12 -> 1125.8404 | N12: 12 | O12: 516.12 | P12: =+O12/9.5 -> 54.328421 | Q12: =+P12*N12 -> 651.94105 | S12: =+Q12+R12 -> 651.94105 | U12: 45786 | V12: =+S12+L12 -> 1777.7815 | W12: 16542.875
D13: 45787 | G13: 10.08 | H13: 870.96774 | I13: =+H13/9.5 -> 91.680815 | J13: =+I13*G13 -> 924.14261 | L13: =+J13+K13 -> 924.14261 | N13: 9.18 | O13: 516.12 | P13: =+O13/9.5 -> 54.328421 | Q13: =+P13*N13 -> 498.73491 | S13: =+Q13+R13 -> 498.73491 | U13: 45787 | V13: =+S13+L13 -> 1422.8775 | W13: 11656.875
D14: 45788 | G14: 0 | H14: 870.96774 | I14: =+H14/9.5 -> 91.680815 | J14: =+I14*G14 -> 0 | K14: 870.96774 | L14: =+J14+K14 -> 870.96774 | N14: 0 | O14: 516.12 | P14: =+O14/9.5 -> 54.328421 | Q14: =+P14*N14 -> 0 | R14: 516.12903 | S14: =+Q14+R14 -> 516.12903 | U14: 45788 | V14: =+S14+L14 -> 1387.0968 | W14: 0
D15: 45789 | G15: 9.26 | H15: 870.96774 | I15: =+H15/9.5 -> 91.680815 | J15: =+I15*G15 -> 848.96435 | L15: =+J15+K15 -> 848.96435 | N15: 0 | O15: 516.12 | P15: =+O15/9.5 -> 54.328421 | Q15: =+P15*N15 -> 0 | S15: =+Q15+R15 -> 0 | U15: 45789 | V15: =+S15+L15 -> 848.96435 | W15: 11583.75
D16: 45790 | G16: 12.38 | H16: 870.96774 | I16: =+H16/9.5 -> 91.680815 | J16: =+I16*G16 -> 1135.0085 | L16: =+J16+K16 -> 1135.0085 | N16: 0 | O16: 516.12 | P16: =+O16/9.5 -> 54.328421 | Q16: =+P16*N16 -> 0 | S16: =+Q16+R16 -> 0 | U16: 45790 | V16: =+S16+L16 -> 1135.0085 | W16: 13642.875
D17: 45791 | G17: 12.05 | H17: 870.96774 | I17: =+H17/9.5 -> 91.680815 | J17: =+I17*G17 -> 1104.7538 | L17: =+J17+K17 -> 1104.7538 | N17: 0 | O17: 516.12 | P17: =+O17/9.5 -> 54.328421 | Q17: =+P17*N17 -> 0 | S17: =+Q17+R17 -> 0 | U17: 45791 | V17: =+S17+L17 -> 1104.7538 | W17: 15322
D18: 45792 | G18: 11.31 | H18: 870.96774 | I18: =+H18/9.5 -> 91.680815 | J18: =+I18*G18 -> 1036.91 | L18: =+J18+K18 -> 1036.91 | N18: 0 | O18: 516.12 | P18: =+O18/9.5 -> 54.328421 | Q18: =+P18*N18 -> 0 | S18: =+Q18+R18 -> 0 | U18: 45792 | V18: =+S18+L18 -> 1036.91 | W18: 15938
D19: 45793 | G19: 9.3 | H19: 870.96774 | I19: =+H19/9.5 -> 91.680815 | J19: =+I19*G19 -> 852.63158 | L19: =+J19+K19 -> 852.63158 | N19: 0 | O19: 516.12 | P19: =+O19/9.5 -> 54.328421 | Q19: =+P19*N19 -> 0 | S19: =+Q19+R19 -> 0 | U19: 45793 | V19: =+S19+L19 -> 852.63158 | W19: 12700
D20: 45794 | G20: 11.58 | H20: 870.96774 | I20: =+H20/9.5 -> 91.680815 | J20: =+I20*G20 -> 1061.6638 | L20: =+J20+K20 -> 1061.6638 | N20: 11.57 | O20: 516.12 | P20: =+O20/9.5 -> 54.328421 | Q20: =+P20*N20 -> 628.57983 | S20: =+Q20+R20 -> 628.57983 | U20: 45794 | V20: =+S20+L20 -> 1690.2437 | W20: 15607
D21: 45795 | G21: 9.24 | H21: 870.96774 | I21: =+H21/9.5 -> 91.680815 | J21: =+I21*G21 -> 847.13073 | K21: 870.96774 | L21: =+J21+K21 -> 1718.0985 | N21: 9.25 | O21: 516.12 | P21: =+O21/9.5 -> 54.328421 | Q21: =+P21*N21 -> 502.53789 | R21: 516.12903 | S21: =+Q21+R21 -> 1018.6669 | U21: 45795 | V21: =+S21+L21 -> 2736.7654 | W21: 13100
D22: 45796 | G22: 9.45 | H22: 870.96774 | I22: =+H22/9.5 -> 91.680815 | J22: =+I22*G22 -> 866.3837 | L22: =+J22+K22 -> 866.3837 | N22: 9.46 | O22: 516.12 | P22: =+O22/9.5 -> 54.328421 | Q22: =+P22*N22 -> 513.94686 | S22: =+Q22+R22 -> 513.94686 | U22: 45796 | V22: =+S22+L22 -> 1380.3306 | W22: 11775.125
D23: 45797 | G23: 9.56 | H23: 870.96774 | I23: =+H23/9.5 -> 91.680815 | J23: =+I23*G23 -> 876.46859 | L23: =+J23+K23 -> 876.46859 | N23: 9.55 | O23: 516.12 | P23: =+O23/9.5 -> 54.328421 | Q23: =+P23*N23 -> 518.83642 | S23: =+Q23+R23 -> 518.83642 | U23: 45797 | V23: =+S23+L23 -> 1395.305 | W23: 14170
D24: 45798 | G24: 10.02 | H24: 870.96774 | I24: =+H24/9.5 -> 91.680815 | J24: =+I24*G24 -> 918.64177 | L24: =+J24+K24 -> 918.64177 | N24: 10.02 | O24: 516.12 | P24: =+O24/9.5 -> 54.328421 | Q24: =+P24*N24 -> 544.37078 | S24: =+Q24+R24 -> 544.37078 | U24: 45798 | V24: =+S24+L24 -> 1463.0125 | W24: 17514
D25: 45799 | G25: 12.04 | H25: 870.96774 | I25: =+H25/9.5 -> 91.680815 | J25: =+I25*G25 -> 1103.837 | L25: =+J25+K25 -> 1103.837 | N25: 12 | O25: 516.12 | P25: =+O25/9.5 -> 54.328421 | Q25: =+P25*N25 -> 651.94105 | S25: =+Q25+R25 -> 651.94105 | U25: 45799 | V25: =+S25+L25 -> 1755.7781 | W25: 15973
D26: 45800 | G26: 12.03 | H26: 870.96774 | I26: =+H26/9.5 -> 91.680815 | J26: =+I26*G26 -> 1102.9202 | L26: =+J26+K26 -> 1102.9202 | N26: 12.04 | O26: 516.12 | P26: =+O26/9.5 -> 54.328421 | Q26: =+P26*N26 -> 654.11419 | S26: =+Q26+R26 -> 654.11419 | U26: 45800 | V26: =+S26+L26 -> 1757.0344 | W26: 17404.5
D27: 45801 | G27: 9.37 | H27: 870.96774 | I27: =+H27/9.5 -> 91.680815 | J27: =+I27*G27 -> 859.04924 | L27: =+J27+K27 -> 859.04924 | N27: 9.38 | O27: 516.12 | P27: =+O27/9.5 -> 54.328421 | Q27: =+P27*N27 -> 509.60059 | S27: =+Q27+R27 -> 509.60059 | U27: 45801 | V27: =+S27+L27 -> 1368.6498 | W27: 13703.75
D28: 45802 | G28: 0 | H28: 870.96774 | I28: =+H28/9.5 -> 91.680815 | J28: =+I28*G28 -> 0 | K28: 870.96774 | L28: =+J28+K28 -> 870.96774 | N28: 0 | O28: 516.12 | P28: =+O28/9.5 -> 54.328421 | Q28: =+P28*N28 -> 0 | R28: 516.12903 | S28: =+Q28+R28 -> 516.12903 | U28: 45802 | V28: =+S28+L28 -> 1387.0968 | W28: 500
D29: 45803 | G29: 11.58 | H29: 870.96774 | I29: =+H29/9.5 -> 91.680815 | J29: =+I29*G29 -> 1061.6638 | L29: =+J29+K29 -> 1061.6638 | N29: 9.24 | O29: 516.12 | P29: =+O29/9.5 -> 54.328421 | Q29: =+P29*N29 -> 501.99461 | S29: =+Q29+R29 -> 501.99461 | U29: 45803 | V29: =+S29+L29 -> 1563.6584 | W29: 10873
D30: 45804 | G30: 9.35 | H30: 870.96774 | I30: =+H30/9.5 -> 91.680815 | J30: =+I30*G30 -> 857.21562 | L30: =+J30+K30 -> 857.21562 | N30: 9.37 | O30: 516.12 | P30: =+O30/9.5 -> 54.328421 | Q30: =+P30*N30 -> 509.05731 | S30: =+Q30+R30 -> 509.05731 | U30: 45804 | V30: =+S30+L30 -> 1366.2729 | W30: 9041.875
D31: 45805 | G31: 12.05 | H31: 870.96774 | I31: =+H31/9.5 -> 91.680815 | J31: =+I31*G31 -> 1104.7538 | L31: =+J31+K31 -> 1104.7538 | N31: 12.04 | O31: 516.12 | P31: =+O31/9.5 -> 54.328421 | Q31: =+P31*N31 -> 654.11419 | S31: =+Q31+R31 -> 654.11419 | U31: 45805 | V31: =+S31+L31 -> 1758.868 | W31: 14867.75
D32: 45806 | G32: 12.03 | H32: 870.96774 | I32: =+H32/9.5 -> 91.680815 | J32: =+I32*G32 -> 1102.9202 | L32: =+J32+K32 -> 1102.9202 | N32: 9.42 | O32: 516.12 | P32: =+O32/9.5 -> 54.328421 | Q32: =+P32*N32 -> 511.77373 | S32: =+Q32+R32 -> 511.77373 | U32: 45806 | V32: =+S32+L32 -> 1614.6939 | W32: 16135
D33: 45807 | G33: 12.09 | H33: 870.96774 | I33: =+H33/9.5 -> 91.680815 | J33: =+I33*G33 -> 1108.4211 | L33: =+J33+K33 -> 1108.4211 | N33: 12.09 | O33: 516.12 | P33: =+O33/9.5 -> 54.328421 | Q33: =+P33*N33 -> 656.83061 | S33: =+Q33+R33 -> 656.83061 | U33: 45807 | V33: =+S33+L33 -> 1765.2517 | W33: 16196
D34: 45808 | G34: 12.1 | H34: 870.96774 | I34: =+H34/9.5 -> 91.680815 | J34: =+I34*G34 -> 1109.3379 | L34: =+J34+K34 -> 1109.3379 | N34: 12.1 | O34: 516.12 | P34: =+O34/9.5 -> 54.328421 | Q34: =+P34*N34 -> 657.37389 | S34: =+Q34+R34 -> 657.37389 | U34: 45808 | V34: =+S34+L34 -> 1766.7118 | W34: 15996
V35: =SUM(V4:V34) -> 48332.457 | W35: =SUM(W4:W34) -> 417039.39 | Y35: =+V35/W35*100 -> 11.589422
D36: June | G36: 27000 | H36: =+G36/30 -> 900 | O36: 16000 | P36: =+O36/30 -> 533.33333 | U36: June
D37: 45809 | G37: 7.06 | H37: 900 | I37: =+H37/100*9.5 -> 85.5 | J37: =+I37*G37 -> 603.63 | K37: 900 | L37: =+J37+K37 -> 1503.63 | N37: 7.07 | O37: 533.33333 | P37: =+O37/9.5 -> 56.140351 | Q37: =+P37*N37 -> 396.91228 | R37: 533.33333 | S37: =+Q37+R37 -> 930.24561 | U37: 45809 | V37: =+S37+L37 -> 2433.8756 | W37: 11500
D38: 45810 | G38: 12.03 | H38: 900 | I38: =+H38/100*9.5 -> 85.5 | J38: =+I38*G38 -> 1028.565 | L38: =+J38+K38 -> 1028.565 | N38: 9.45 | O38: 533.33333 | P38: =+O38/9.5 -> 56.140351 | Q38: =+P38*N38 -> 530.52632 | S38: =+Q38+R38 -> 530.52632 | U38: 45810 | V38: =+S38+L38 -> 1559.0913 | W38: 15005
D39: 45811 | G39: 12.05 | H39: 900 | I39: =+H39/100*9.5 -> 85.5 | J39: =+I39*G39 -> 1030.275 | L39: =+J39+K39 -> 1030.275 | N39: 12.05 | O39: 533.33333 | P39: =+O39/9.5 -> 56.140351 | Q39: =+P39*N39 -> 676.49123 | S39: =+Q39+R39 -> 676.49123 | U39: 45811 | V39: =+S39+L39 -> 1706.7662 | W39: 14801
D40: 45812 | G40: 12.04 | H40: 900 | I40: =+H40/100*9.5 -> 85.5 | J40: =+I40*G40 -> 1029.42 | L40: =+J40+K40 -> 1029.42 | N40: 12.05 | O40: 533.33333 | P40: =+O40/9.5 -> 56.140351 | Q40: =+P40*N40 -> 676.49123 | S40: =+Q40+R40 -> 676.49123 | U40: 45812 | V40: =+S40+L40 -> 1705.9112 | W40: 14754.875
...

Sheet Sheet3
A1: Emp. Code: | D1: Dharmendra Kumar S/o Raghuveer
A2: Days | C2: 1 S | D2: 9 M | E2: 10 T | F2: 11 W | G2: 12 Th | H2: 13 F | I2: 14 St | J2: 15 S | K2: 16 M | L2: 17 T | M2: 18 W | N2: 19 Th | O2: 20 F | P2: 21 St | Q2: 22 S | R2: 23 M | S2: 24 T | T2: 25 W | U2: 26 Th | V2: 27 F | W2: 28 St | X2: 29 S | Y2: 30 M
A3: InTime | C3: 08:59 | E3: 09:03 | F3: 08:58 | G3: 09:02 | H3: 09:00 | I3: 09:00 | J3: 0.375 | K3: 09:02 | L3: 09:05 | M3: 09:10 | N3: 09:03 | O3: 09:04 | P3: 09:05 | R3: 08:53 | S3: 08:51 | T3: 08:53 | U3: 08:51 | V3: 09:03 | W3: 09:02 | X3: 09:05 | Y3: 09:04
A4: OutTime | C4: 16:05 | E4: 19:06 | F4: 21:08 | G4: 21:03 | H4: 21:07 | I4: 21:06 | J4: 0.77569444 | K4: 0.875 | L4: 21:07 | M4: 21:08 | N4: 21:03 | O4: 21:07 | P4: 18:44 | R4: 21:12 | S4: 21:07 | T4: 21:02 | U4: 21:15 | V4: 16:32 | W4: 21:01 | X4: 16:09 | Y4: 21:03
A5: Total | C5: 0.29583333 | D5: 0 | E5: 0.41875 | F5: 0.50694444 | G5: 0.50069444 | H5: 0.50486111 | I5: 0.50416667 | J5: 0.40069444 | K5: 0.49861111 | L5: 0.50138889 | M5: 0.49861111 | N5: 0.5 | O5: 0.50208333 | P5: 0.40208333 | Q5: 0 | R5: 0.51319444 | S5: 0.51111111 | T5: 0.50625 | U5: 0.51666667 | V5: 0.31180556 | W5: 0.49930556 | X5: 0.29444444 | Y5: 0.49930556
A8: Emp. Code: | D8: Pavan Ghanghoria S/O Lakhan ghanghoria
A9: Days | C9: 1 S | D9: 9 M | E9: 10 T | F9: 11 W | G9: 12 Th | H9: 13 F | I9: 14 St | J9: 15 S | K9: 16 M | L9: 17 T | M9: 18 W | N9: 19 Th | O9: 20 F | P9: 21 St | Q9: 22 S | R9: 23 M | S9: 24 T | T9: 25 W | U9: 26 Th | V9: 27 F | W9: 28 St | X9: 29 S | Y9: 30 M
A10: InTime | C10: 0.37430556 | D10: 08:16 | E10: 08:59 | F10: 08:58 | G10: 09:02 | H10: 09:00 | I10: 09:00 | J10: 0.375 | K10: 09:02 | L10: 09:04 | M10: 09:10 | N10: 09:03 | O10: 09:04 | P10: 09:04 | R10: 08:52 | S10: 08:52 | T10: 08:53 | U10: 08:50 | V10: 09:03 | W10: 09:02 | Y10: 09:04
A11: OutTime | C11: 0.67083333 | D11: 18:22 | E11: 19:07 | F11: 21:08 | G11: 21:04 | H11: 21:07 | I11: 21:06 | J11: 0.77569444 | K11: 0.875 | L11: 21:09 | M11: 21:08 | N11: 21:03 | O11: 21:07 | P11: 18:44 | R11: 0.875 | S11: 21:05 | T11: 21:02 | U11: 21:16 | V11: 20:12 | W11: 18:40 | Y11: 18:49
A12: Total | C12: 0.29652778 | D12: 0.42083333 | E12: 0.42222222 | F12: 0.50694444 | G12: 0.50138889 | H12: 0.50486111 | I12: 0.50416667 | J12: 0.40069444 | K12: 0.49861111 | L12: 0.50347222 | M12: 0.49861111 | N12: 0.5 | O12: 0.50208333 | P12: 0.40277778 | Q12: 0 | R12: 0.50555556 | S12: 0.50902778 | T12: 0.50625 | U12: 0.51805556 | V12: 0.46458333 | W12: 0.40138889 | X12: 0 | Y12: 0.40625
D23: Indivisible
D25: Pawan | E25: 16000 | F25: =+E25*12 -> 192000 | G25: 306 | H25: =+F25/G25 -> 627.45098 | I25: =+H25/9.5 -> 66.047472
D26: Dharmander | E26: 27000 | F26: =+E26*12 -> 324000 | G26: 306 | H26: =+F26/G26 -> 1058.8235 | I26: =+H26/9.5 -> 111.45511
D27: Ankit | E27: 11500 | F27: =+E27*12 -> 138000 | G27: 306 | H27: =+F27/G27 -> 450.98039 | I27: =+H27/9.5 -> 47.47162
D28: Shekar | E28: 17000 | F28: =+E28*12 -> 204000 | G28: 306 | H28: =+F28/G28 -> 666.66667 | I28: =+H28/9.5 -> 70.175439
D29: Tasavr | E29: =300 -> 300 | H29: 300 | I29: =+H29/8 -> 37.5
D30: Taiyab | E30: 19500 | F30: =+E30*12 -> 234000 | G30: 306 | H30: =+F30/G30 -> 764.70588 | I30: =+H30/12 -> 63.72549
D31: Rajan Kushwaha | E31: 7500 | F31: =+E31*12 -> 90000 | G31: 306 | H31: =+F31/G31 -> 294.11765 | I31: =+H31/12 -> 24.509804
